Workbook

Sheet LOI and Commissioning Master Sh
A1: Basis Information | W1: Information Shared with MSO | AF1: To be Filled By DO | AT1: To be Filled by FO | BK1: To be Filled by Engineers- for A sites SM(Engg) and for B sites by Area Engineer | BW1: by DO
A2: SN | B2: Name of Location | C2: Loi Holder Name | D2: Retail Sales Area | E2: SN of Location | F2: LOI Holder contact details | G2: Market Class | H2: Type | I2: RO/KSK | J2: TYPE OF SITE | K2: Letter of Intent Number | L2: Marketing Plan | M2: LOI Date | N2: LOI Age | O2: LOI Age Analysis | P2: District | Q2: Description | R2: Land Offer | S2: Motor Spirit Potential | T2: HSD Potential | U2: Total Potential | V2: Strategic | W2: Commissionable | X2: Comm. Plan in FY26-27 | Y2: IO Available/If not available target month (MMM-YY format) | Z2: Advanced Tender Approval Status | AA2: NA Available (Y/N) | AB2: PESO CA Available (Y/N) | AC2: NOC Available (Y/N) | AD2: NOC Month | AE2: Comm. Month | AF2: Commissionable | AG2: Case of Non-Commissionable | AH2: LOI cancellation | AI2: Valuation if applicable | AJ2: Negotiations if applicable | AK2: NOC Available | AL2: Expected Month of NOC | AM2: Concept Note | AN2: Estimate | AO2: Note Draft | AP2: IO Available | AQ2: IO NO | AR2: IO Reamrk | AS2: Expected Month of commissioning-Actual | AT2: LOI Collected (Yes/No) | AU2: LOI Commissionable (Yes/Yes but in next FY/No) | AV2: Reason for Non Commissionable and Commissionable in Next FY | AW2: If Non Commissionabl, whether recommended for Cancellation (Yes/No) | AX2: NOC Applied | AY2: Mojnai (Yet to Apply/Applied/Received/NA) | AZ2: Building Plan Approval and NA (Yet to Apply/Applied/Received/NA) | BA2: Police (Yet to Apply/Applied/Received/NA) | BB2: NH/PWD (Yet to Apply/Applied/Received/NA) | BC2: MSEB (Yet to Apply/Applied/Received/NA) | BD2: Dy Dir Industrial safety (Yet to Apply/Applied/Received/NA) | BE2: Wild Life (Yet to Apply/Applied/Received/NA) | BF2: Forest (Yet to Apply/Applied/Received/NA) | BG2: LSR only (Yet to Assign/In Process/Received) | BH2: Site Readiness (Yes/No/WIP) | BI2: Expected Month of NOC (MMM-YY) | BJ2: Expected Month of Commg (MMM-YY) | BK2: Layout Drawing (Yes/No/Moujani Awaited) | BL2: PESO Prior (Yet to Apply/Applied/Received) | BM2: BOQ Sent for Approved Cases (Yes/No/NA) | BN2: Advance Tender Status(Yet to Publish/Published/Awarded/NA/Approval Awaited) | BO2: Tender Publication by RCC Date | BP2: WO Number (NOC/IO Awaited) | BQ2: WO Date | BR2: Name of Contractor | BS2: WO Completion Target Date Date | BT2: Date of Site Handing Over | BU2: Expected Date of Commissioning | BV2: PESO Final License Status (Applied/Received/Yet to Apply) | BW2: Final Commissioning Status | BX2: SAP Code | BY2: RO Name | BZ2: LSR assigned to | CA2: Valuation assigned to | CB2: SRMP | CC2: LOI as on 01.04.2026 | CD2: MOU Target | CE2: LOA No | CF2: SAP Code | CG2: Name of RO | CH2: WIP | CI2: LOI Month | CJ2: Category | CK2: MOU | CL2: Committed to SO | CM2: Admin Approval reference NO | CN2: Pending With
A3: 119 | B3: Village Yelse on MDR (Pawna lake to Kamshet Road) | C3: DIKSHA SACHIN SONAWANE | D3: Pune Tathawade RSA | E3: 2112 | F3: 9767902929 | G3: E | H3: A | I3: KSK | J3: KSK-A w/o Reco | K3: R/2023/IN003356/MAH/000373/3203/00114 | L3: 2023-24 | M3: 45315 | N3: =+TODAY()-M3 -> 862 | O3: =+IF(N3<180,"0-6M",IF(N3<365,"6-12M",IF(N3<730,"1-2Y",IF(N3<1095,"2-3Y",IF(N3<1460,"3-4Y",IF(N3<1825,"4-5Y",IF(N3>1825,">5Y"))))))) -> 2-3Y | P3: PUNE | Q3: SC | R3: Group 1: Owned land | S3: 30 | T3: 90 | U3: =+S3+T3 -> 120 | W3: Yes | X3: Yes | Y3: =+AP3 -> Yes | Z3: Approved | AC3: Yes | AD3: =+AL3 -> 46082 | AE3: =+AS3 -> 46113 | AF3: Yes | AG3: NA | AH3: NA | AI3: Yes | AJ3: Yes | AK3: Available | AL3: 46082 | AM3: Yes | AN3: Yes | AO3: Approved | AP3: Yes | AQ3: 4337839 | AS3: 46113 | AT3: Yes | AU3: Yes | AV3: LOI holder asking for recon at LOI stage, LSR has come dtd 24.07.24 | AW3: NA | AX3: Yes | AY3: Yes | AZ3: Yes | BA3: Received | BB3: Not Required | BC3: Received | BD3: Received | BE3: NA | BF3: NA | BG3: Received | BH3: Yes | BI3: 46113 | BJ3: 46113 | BK3: Yes | BL3: Received | BN3: Yes | BW3: Commissioned | BX3: 391546 | BY3: Sai Veenit Petroleum | CB3: SRMP 2023-24 | CC3: Yes | CD3: Yes | CF3: 391546 | CG3: Sai Veenit Petroleum | CH3: Yes | CI3: =TEXT(M3,"MMM'YY") -> Jan'24 | CJ3: SC | CK3: Yes | CL3: Yes
A4: 70 | B4: From Kalas to Rui Village on MDR via Gosaviwadi | C4: VIJAY BABAN KALE | D4: Pune Saswad RSA | E4: 2110 | F4: 7499292270 | G4: E | H4: B | I4: KSK | J4: KSK-B w/o Reco | K4: R/2023/IN000625/MAH/000058/3203/00018 | L4: 2023-24 | M4: 45249 | N4: =+TODAY()-M4 -> 928 | O4: =+IF(N4<180,"0-6M",IF(N4<365,"6-12M",IF(N4<730,"1-2Y",IF(N4<1095,"2-3Y",IF(N4<1460,"3-4Y",IF(N4<1825,"4-5Y",IF(N4>1825,">5Y"))))))) -> 2-3Y | P4: PUNE | Q4: OPEN | R4: Group 1: Owned land | S4: 30 | T4: 51 | U4: =+S4+T4 -> 81 | W4: Yes | X4: Yes | Y4: =+AP4 -> Yes | Z4: NA | AC4: Yes | AD4: =+AL4 -> 46143 | AE4: =+AS4 -> 46143 | AF4: Yes | AG4: NA | AH4: NA | AI4: Not Required | AJ4: Not Required | AK4: Available | AL4: 46143 | AM4: Yes | AN4: Yes | AO4: Approved | AP4: Yes | AQ4: 4337720 | AS4: 46143 | AT4: Yes | AU4: Yes | AW4: NA | AX4: Yes | AY4: Yes | AZ4: Received | BA4: Received | BB4: Received | BC4: Received | BD4: Received | BE4: NA | BF4: NA | BG4: Received | BH4: Yes | BI4: 46168 | BJ4: 46168 | BK4: Yes | BL4: Received | BM4: NA | BN4: NA | BO4: Not Required | BP4: 72293969 | BQ4: 18.05.2026 | BR4: PC ENGINEERING CONTRACTORS | BS4: 29.06.2026 | BT4: 19.05.2026 | BV4: Applied | BW4: Commissioned | BX4: 393129 | BY4: Vijayraj Petroleum | CB4: SRMP 2023-24 | CC4: Yes | CD4: Yes | CI4: =TEXT(M4,"MMM'YY") -> Nov'23 | CJ4: Open | CK4: Yes | CL4: Yes
A5: 75 | B5: From KM stone 33 to 35 on LHS of Khandala Lonand Road | C5: SHEKHAR HANAMANT YADAV | D5: Satara East RSA | E5: 2109 | F5: 7387890252 | G5: E | H5: B | I5: KSK | J5: KSK-B w/o Reco | K5: R/2023/IN001265/MAH/000090/3203/00031 | L5: 2023-24 | M5: 45264 | N5: =+TODAY()-M5 -> 913 | O5: =+IF(N5<180,"0-6M",IF(N5<365,"6-12M",IF(N5<730,"1-2Y",IF(N5<1095,"2-3Y",IF(N5<1460,"3-4Y",IF(N5<1825,"4-5Y",IF(N5>1825,">5Y"))))))) -> 2-3Y | P5: SATARA | Q5: OPEN | R5: Group 1: Owned land | S5: 20 | T5: 80 | U5: =+S5+T5 -> 100 | W5: Yes | X5: Yes | Z5: NA | AC5: Yes | AD5: 46143 | AE5: 46143 | AF5: Yes | AG5: NA | AH5: NA | AI5: Not Required | AJ5: Not Required | AK5: Available | AL5: 46143 | AM5: Yes | AN5: Yes | AO5: Approved | AP5: Yes | AQ5: 4338576 | AS5: 46143 | AT5: Yes | AU5: Yes | AV5: NA | AW5: NA | AX5: Yes | AY5: Received | AZ5: Received | BA5: Received | BB5: Received | BC5: Received | BD5: NA | BE5: NA | BF5: NA | BG5: Received | BH5: WIP | BI5: 46148 | BJ5: 46143 | BK5: Yes | BL5: Received | BM5: NA | BN5: NA | BO5: Not Required | BW5: Commissioned | BX5: 392992 | BY5: Bhairavnath Petroleum | CB5: SRMP 2023-24 | CC5: Yes | CD5: Yes | CI5: =TEXT(M5,"MMM'YY") -> Dec'23 | CJ5: Open | CK5: Yes | CL5: Yes
A6: 79 | B6: WITHIN 5 KM FROM DHEBEWADI PHATA KARAD TOWARDS SATARA ON LHS OF KARAD TO SATARA ROAD | C6: CHINMAY ARVIND GHATE | D6: Satara West RSA | E6: 1925 | F6: 9604101182 | G6: D1 | H6: B | I6: RO | J6: RO B Site | K6: R/2023/IN001436/MAH/000103/3203/00039 | L6: 2023-24 | M6: 45271 | N6: =+TODAY()-M6 -> 906 | O6: =+IF(N6<180,"0-6M",IF(N6<365,"6-12M",IF(N6<730,"1-2Y",IF(N6<1095,"2-3Y",IF(N6<1460,"3-4Y",IF(N6<1825,"4-5Y",IF(N6>1825,">5Y"))))))) -> 2-3Y | P6: SATARA | Q6: OPEN | R6: Group 1: Owned land | S6: 30 | T6: 120 | U6: =+S6+T6 -> 150 | W6: Yes | X6: Yes | Y6: =+AP6 -> Yes | Z6: NA | AC6: Yes | AD6: =+AL6 -> 46143 | AE6: =+AS6 -> 46143 | AF6: Yes | AG6: NA | AH6: NA | AI6: Not Required | AJ6: Not Required | AK6: Available | AL6: 46143 | AM6: Yes | AN6: Yes | AO6: Approved | AP6: Yes | AQ6: 4337806 | AS6: 46143 | AT6: YES | AU6: YES | AV6: NA | AW6: NA | AX6: YES | AY6: Received | AZ6: Received | BA6: Received | BB6: Applied | BC6: Received | BD6: NA | BE6: NA | BF6: NA | BG6: Received | BH6: WIP | BI6: 46168 | BJ6: 46199 | BK6: Yes | BL6: Received | BM6: NA | BN6: NA | BO6: Not Required | BW6: Commissioned | BX6: 393128 | BY6: Krishna Petroleum and Energy Hub | CB6: SRMP 2023-24 | CC6: Yes | CD6: Yes | CI6: =TEXT(M6,"MMM'YY") -> Dec'23 | CJ6: Open | CK6: Yes | CL6: Yes
A7: 123 | B7: From Jadhavwadi to Laxmi Chowk on DP Road | C7: MAYUR SUNIL BORATE | D7: Pimpri Chinchwad RSA | E7: 1801 | F7: 7720000414 | G7: A | H7: A | I7: RO | J7: RO A Site | K7: R/2023/IN003596/MAH/000399/3203/00122 | L7: 2023-24 | M7: 45322 | N7: =+TODAY()-M7 -> 855 | O7: =+IF(N7<180,"0-6M",IF(N7<365,"6-12M",IF(N7<730,"1-2Y",IF(N7<1095,"2-3Y",IF(N7<1460,"3-4Y",IF(N7<1825,"4-5Y",IF(N7>1825,">5Y"))))))) -> 2-3Y | P7: PUNE | Q7: OPEN | R7: Group 1: Owned land | S7: 150 | T7: 50 | U7: =+S7+T7 -> 200 | W7: Yes | X7: Yes | Y7: =+AP7 -> Yes | Z7: Approved | AA7: Yes | AB7: Yes | AC7: Yes | AD7: =+AL7 -> 46113 | AE7: =+AS7 -> 46143 | AF7: Yes | AG7: NA | AH7: NA | AI7: Yes | AJ7: Yes | AK7: Available | AL7: 46113 | AM7: Yes | AN7: Yes | AO7: Approved | AP7: Yes | AQ7: 4337869 | AS7: 46143 | AT7: Yes | AU7: Yes | AV7: NA | AW7: NA | AX7: Yes | AY7: Received | AZ7: Received | BA7: Received | BB7: Not Required | BC7: Received | BD7: Received | BE7: NA | BF7: NA | BG7: Received | BH7: Yes | BI7: 46113 | BJ7: 46143 | BK7: Yes | BL7: Received | BN7: Yes | BW7: Commissioned | BX7: 392301 | BY7: S N Borate Petroleum | CB7: SRMP 2023-24 | CC7: Yes | CD7: Yes | CH7: Yes | CI7: =TEXT(M7,"MMM'YY") -> Jan'24 | CJ7: Open | CK7: Yes | CL7: Yes
A8: 172 | B8: Within 6 Km from Atmaram Baba Mandir,Mandali towards Solapur on Ahmednagar-Solapur NH | C8: RAMAN PANDHARINATH KHULE | D8: Ahmednagar West RSA | E8: 1721 | F8: 8329858727 | G8: D1 | H8: B | I8: RO | J8: RO B Site | K8: R/2024/IN002364/MAH/000194/3203/00029 | L8: 2023-24 | M8: 45460 | N8: =+TODAY()-M8 -> 717 | O8: =+IF(N8<180,"0-6M",IF(N8<365,"6-12M",IF(N8<730,"1-2Y",IF(N8<1095,"2-3Y",IF(N8<1460,"3-4Y",IF(N8<1825,"4-5Y",IF(N8>1825,">5Y"))))))) -> 1-2Y | P8: AHMADNAGAR | Q8: OPEN | R8: Group 1: Owned land | S8: 30 | T8: 123 | U8: =+S8+T8 -> 153 | W8: Yes | X8: Yes | Y8: =+AP8 -> Yes | Z8: NA | AD8: =+AL8 -> 46143 | AE8: =+AS8 -> 46143 | AF8: Yes | AG8: NA | AH8: NA | AI8: Not Required | AJ8: Not Required | AK8: Available | AL8: 46143 | AM8: Yes | AN8: Yes | AO8: Approved | AP8: Yes | AQ8: 4338116 | AS8: 46143 | AT8: Yes | AU8: Yes | AV8: NA | AW8: NA | AX8: Yes | AY8: Received | AZ8: Received | BA8: Received | BB8: Received | BC8: NA | BD8: NA | BE8: Received | BF8: Received | BG8: Received | BH8: Yes | BI8: 46082 | BJ8: 46143 | BK8: Yes | BL8: Received | BM8: NA | BN8: NA | BO8: Not Required | BW8: Commissioned | BX8: 392938 | BY8: Gangagiri Petroleum | CB8: SRMP 2023-24 | CC8: Yes | CD8: Yes | CH8: Yes | CI8: =TEXT(M8,"MMM'YY") -> Jun'24 | CJ8: Open | CK8: Yes | CL8: Yes
A9: 203 | B9: From Bhigwan Circle to Dalaj Phata on RHS of Pune- Solapur Highway | C9: KUNDALIK UTTAM KAMBLE | D9: Pune Saswad RSA | E9: 1665 | F9: 9960252231 | G9: D1 | H9: A | I9: RO | J9: RO A Site-Corpu | K9: R/2024/IN002520/MAH/000255/3203/00078 | L9: 2023-24 | M9: 45463 | N9: =+TODAY()-M9 -> 714 | O9: =+IF(N9<180,"0-6M",IF(N9<365,"6-12M",IF(N9<730,"1-2Y",IF(N9<1095,"2-3Y",IF(N9<1460,"3-4Y",IF(N9<1825,"4-5Y",IF(N9>1825,">5Y"))))))) -> 1-2Y | P9: PUNE | Q9: SC | R9: Group 2: Firm Offer | S9: 30 | T9: 130 | U9: =+S9+T9 -> 160 | W9: Yes | X9: Yes | Y9: =+AP9 -> Yes | Z9: Approved | AC9: Yes | AD9: =+AL9 -> 46113 | AE9: =+AS9 -> 46143 | AF9: Yes | AG9: NA | AH9: NA | AI9: Yes | AJ9: Yes | AK9: Available | AL9: 46113 | AM9: Yes | AN9: Yes | AO9: Approved | AP9: Yes | AQ9: 4338194 | AS9: 46143 | AT9: Yes | AU9: Yes | AV9: NA | AW9: NA | AX9: Yes | AY9: Yes | AZ9: Received | BA9: Received | BB9: Received | BC9: Received | BD9: Received | BE9: NA | BF9: NA | BG9: Received | BH9: Yes | BI9: 46107 | BJ9: 46168 | BK9: Yes | BL9: Received | BN9: Yes | BW9: Commissioned | BX9: 392994 | BY9: Mauli Petroleum | CB9: SRMP 2023-24 | CC9: Yes | CD9: Yes | CE9: R/2026/IN000139/3203/00004 | CI9: =TEXT(M9,"MMM'YY") -> Jun'24 | CJ9: SC | CK9: Yes | CL9: Yes
A10: 218 | B10: At Village Karhavagaj on Jejuri-Morgaon-Baramati Road | C10: BALASAHEB LIMBAJI AGAWANE | D10: Pune Tathawade RSA | E10: 1736 | F10: 9922414802 | G10: D2 | H10: A | I10: RO | J10: RO A Site-Corpu | K10: R/2024/IN003547/MAH/000391/3203/00107 | L10: 2023-24 | M10: 45547 | N10: =+TODAY()-M10 -> 630 | O10: =+IF(N10<180,"0-6M",IF(N10<365,"6-12M",IF(N10<730,"1-2Y",IF(N10<1095,"2-3Y",IF(N10<1460,"3-4Y",IF(N10<1825,"4-5Y",IF(N10>1825,">5Y"))))))) -> 1-2Y | P10: PUNE | Q10: SC | R10: Group 1: Owned land | S10: 30 | T10: 80 | U10: =+S10+T10 -> 110 | W10: Yes | X10: Yes | Y10: =+IF(AO10="Approved","Yes",AS10) -> Yes | Z10: Approved | AA10: Yes | AB10: No | AC10: Yes | AD10: =+AL10 -> 46143 | AE10: =+AS10 -> 46143 | AF10: Yes | AG10: NA | AH10: NA | AI10: Yes | AJ10: Yes | AK10: Available | AL10: 46143 | AM10: Yes | AN10: Yes | AO10: Approved | AP10: Yes | AQ10: 4338515 | AS10: 46143 | AT10: Yes | AU10: Yes | AV10: DM NOC received on 08.05.2026 | AW10: NA | AX10: Yes | AY10: Yes | AZ10: Yes | BA10: Received | BB10: Received | BC10: Received | BD10: Received | BE10: NA | BF10: NA | BG10: Received | BH10: WIP | BI10: 46054 | BJ10: 46327 | BK10: Yes | BL10: Received | BN10: Yes | BW10: Commissioned | BX10: 393015 | BY10: Ahilya Petroleum | CB10: SRMP 2023-24 | CC10: Yes | CD10: Yes | CE10: R/2026/IN000141/3203/00005 | CI10: =TEXT(M10,"MMM'YY") -> Sep'24 | CJ10: SC | CK10: Yes | CL10: Yes
A11: 62 | B11: AT VADAPURI ON LHS OF INDAPUR-AKLUJ ROAD , | C11: VISHRAM MORE | D11: Pune Saswad RSA | F11: 9850601522 | G11: D1 | H11: A | I11: RO | J11: RO A Site-Corpu | K11: M/2022/IN001731/MAH/000117/3203/00043 | L11: 2018-19 | M11: 45012 | N11: =+TODAY()-M11 -> 1165 | O11: =+IF(N11<180,"0-6M",IF(N11<365,"6-12M",IF(N11<730,"1-2Y",IF(N11<1095,"2-3Y",IF(N11<1460,"3-4Y",IF(N11<1825,"4-5Y",IF(N11>1825,">5Y"))))))) -> 3-4Y | P11: PUNE | Q11: ST | R11: Group 2: Firm Offer | S11: 40 | T11: 110 | U11: =+S11+T11 -> 150 | W11: Yes | X11: Yes | Y11: =+IF(AO11="Approved","Yes",AS11) -> 46174 | Z11: Approved | AD11: =+AL11 -> 46174 | AE11: =+AS11 -> 46174 | AF11: Yes | AG11: NA | AH11: NA | AI11: Yes | AJ11: Yes | AL11: 46174 | AM11: Yes | AN11: Yes | AO11: Sent | AP11: No | AS11: 46174 | AT11: Yes | AU11: Yes | AV11: LSR dtd 11.05.2023. Supple LSR dtd 29.07.24 has come- IO to be taken | AW11: NA | AX11: Yes | AY11: Yes | AZ11: Received | BA11: Received | BB11: Applied | BC11: Received | BD11: Received | BE11: NA | BF11: NA | BG11: Received | BH11: Yes | BI11: 46199 | BJ11: 46199 | BK11: Yes | BL11: Received | BN11: Pending | BW11: Pending | CB11: SRMP 2018-19 | CC11: Yes | CD11: Yes | CI11: =TEXT(M11,"MMM'YY") -> Mar'23 | CJ11: st | CK11: Yes | CL11: Yes | CM11: Administrative Approval/3203/SL01/2025-2026/138315
A12: 72 | B12: Within 3 KM from Akshata Mangal Karyalaya towards Taklibhan on Shrirampur Nevasa SH | C12: PRASAD BALASAHEB CHAUDHARI | D12: Ahmednagar East RSA | E12: 1818 | F12: 9822603682 | G12: D2 | H12: B | I12: RO | J12: RO B Site | K12: R/2023/IN000927/MAH/000071/3203/00022 | L12: 2023-24 | M12: 45257 | N12: =+TODAY()-M12 -> 920 | O12: =+IF(N12<180,"0-6M",IF(N12<365,"6-12M",IF(N12<730,"1-2Y",IF(N12<1095,"2-3Y",IF(N12<1460,"3-4Y",IF(N12<1825,"4-5Y",IF(N12>1825,">5Y"))))))) -> 2-3Y | P12: AHMADNAGAR | Q12: OBC | R12: Group 1: Owned land | S12: 30 | T12: 85 | U12: =+S12+T12 -> 115 | W12: Yes | X12: Yes | Y12: =+AP12 -> Yes | Z12: NA | AD12: =+AL12 -> 46143 | AE12: 46174 | AF12: Yes | AG12: NA | AH12: NA | AI12: Not Required | AJ12: Not Required | AL12: 46143 | AM12: Yes | AN12: Yes | AO12: Approved | AP12: Yes | AQ12: 4337692 | AS12: 46174 | AT12: Yes | AU12: Yes | AV12: NA | AW12: NA | AX12: Yes | AY12: Received | AZ12: Applied | BA12: Received | BB12: Received | BC12: Received | BD12: NA | BE12: Received | BF12: Received | BG12: Received | BH12: Yes | BI12: 46174 | BJ12: 46174 | BK12: Yes | BL12: Received | BM12: NA | BN12: NA | BO12: Not Required | BW12: Pending | CB12: SRMP 2023-24 | CC12: Yes | CD12: Yes | CI12: =TEXT(M12,"MMM'YY") -> Nov'23 | CJ12: OBC | CK12: Yes | CL12: Yes
A13: 96 | B13: From Kasar-Dumala to Chikhali on Sangamner Akole SH | C13: MADHURI RAVINDRA SHENKAR | D13: Shirdi RSA | E13: 1954 | F13: 9156559088 | G13: D2 | H13: A | I13: RO | J13: RO A Site-Corpu | K13: R/2023/IN001869/MAH/000198/3203/00074 | L13: 2023-24 | M13: 45279 | N13: =+TODAY()-M13 -> 898 | O13: =+IF(N13<180,"0-6M",IF(N13<365,"6-12M",IF(N13<730,"1-2Y",IF(N13<1095,"2-3Y",IF(N13<1460,"3-4Y",IF(N13<1825,"4-5Y",IF(N13>1825,">5Y"))))))) -> 2-3Y | P13: AHMADNAGAR | Q13: ST | R13: Group 1: Owned land | S13: 30 | T13: 85 | U13: =+S13+T13 -> 115 | W13: Yes | X13: Yes | Y13: =+AP13 -> Yes | Z13: Approved | AD13: =+AL13 -> 46143 | AE13: =+AS13 -> 46174 | AF13: Yes | AG13: NA | AH13: NA | AI13: Yes | AJ13: Yes | AL13: 46143 | AM13: Yes | AN13: Yes | AO13: Approved | AP13: Yes | AQ13: 4338093 | AS13: 46174 | AT13: Yes | AU13: Yes | AV13: NA | AW13: NA | AX13: Yes | AY13: Recieved | AZ13: Applied | BA13: Recieved | BB13: Recieved | BC13: Recived | BD13: NA | BE13: Recived | BF13: Recived | BG13: Received | BH13: WIP | BI13: 46193 | BJ13: 46265 | BK13: Yes | BL13: Received | BN13: Pending | BW13: Pending | CB13: SRMP 2023-24 | CC13: Yes | CD13: Yes | CI13: =TEXT(M13,"MMM'YY") -> Dec'23 | CJ13: st | CK13: Yes | CL13: Yes
A14: 103 | B14: On RHS of Pune-Solapur NH, From Vangali to intersection of Indapur Bypass & Baramati Highway | C14: OMKAR GIRISH SHAH | D14: Pune Saswad RSA | E14: 1897 | F14: 9730606767 | G14: D1 | H14: A | I14: RO | J14: RO A Site | K14: R/2023/IN002958/MAH/000314/3203/00093 | L14: 2023-24 | M14: 45307 | N14: =+TODAY()-M14 -> 870 | O14: =+IF(N14<180,"0-6M",IF(N14<365,"6-12M",IF(N14<730,"1-2Y",IF(N14<1095,"2-3Y",IF(N14<1460,"3-4Y",IF(N14<1825,"4-5Y",IF(N14>1825,">5Y"))))))) -> 2-3Y | P14: PUNE | Q14: OPEN | R14: Group 1: Owned land | S14: 30 | T14: 120 | U14: =+S14+T14 -> 150 | W14: Yes | X14: Yes | Y14: =+AP14 -> Yes | Z14: Approved | AD14: =+AL14 -> 46143 | AE14: =+AS14 -> 46174 | AF14: Yes | AG14: NA | AH14: NA | AI14: Yes | AJ14: Yes | AL14: 46143 | AM14: Yes | AN14: Yes | AO14: Approved | AP14: Yes | AQ14: 4337433 | AS14: 46174 | AT14: Yes | AU14: Yes | AV14: All NOCs are send for revalidation and awaited | AW14: NA | AX14: Yes | AY14: Yes | AZ14: Received | BA14: Received | BB14: Received | BC14: Received | BD14: Received | BE14: NA | BF14: NA | BG14: Received | BH14: Yes | BI14: 46174 | BJ14: 46199 | BK14: Yes | BL14: Received | BN14: Yes | BW14: Pending | CB14: SRMP 2023-24 | CC14: Yes | CD14: Yes | CI14: =TEXT(M14,"MMM'YY") -> Jan'24 | CJ14: Open | CK14: Yes | CL14: Yes
A15: 140 | B15: FROM SHITPUR PHATA TO NIMBODI PHATA ON SHRIGONDA - JAMKHED ROAD | C15: PRASHANT BAPURAO GAIKWADE | D15: Ahmednagar West RSA | E15: 1738 | F15: 9960968999 | G15: D1 | H15: B | I15: RO | J15: RO B Site | K15: R/2023/IN004897/MAH/000498/3203/00150 | L15: 2023-24 | M15: 45349 | N15: =+TODAY()-M15 -> 828 | O15: =+IF(N15<180,"0-6M",IF(N15<365,"6-12M",IF(N15<730,"1-2Y",IF(N15<1095,"2-3Y",IF(N15<1460,"3-4Y",IF(N15<1825,"4-5Y",IF(N15>1825,">5Y"))))))) -> 2-3Y | P15: AHMADNAGAR | Q15: OPEN | R15: Group 1: Owned land | S15: 30 | T15: 120 | U15: =+S15+T15 -> 150 | W15: Yes | X15: Yes | Y15: =+AP15 -> Yes | Z15: NA | AD15: =+AL15 -> 46143 | AE15: =+AS15 -> 46174 | AF15: Yes | AG15: NA | AH15: NA | AI15: Not Required | AJ15: Not Required | AK15: Available | AL15: 46143 | AM15: Yes | AN15: Yes | AO15: Approved | AP15: Yes | AQ15: 4338435 | AR15: NHAI Access Pending | AS15: 46174 | AT15: Yes | AU15: Yes | AV15: NA | AW15: NA | AX15: Yes | AY15: Received | AZ15: Received | BA15: Received | BB15: Applied | BC15: NA | BD15: NA | BE15: Received | BF15: Received | BG15: Received | BH15: Yes | BI15: 46143 | BJ15: 46143 | BK15: Yes | BL15: Received | BM15: NA | BN15: NA | BO15: Not Required | BR15: PVT. LTD. | BW15: Pending | CB15: SRMP 2023-24 | CC15: Yes | CD15: Yes | CI15: =TEXT(M15,"MMM'YY") -> Feb'24 | CJ15: Open | CK15: Yes | CL15: Yes
A16: 139 | B16: From Navnagapur to Shendi on Shendi Bypass | C16: AKSHAY PRAKASH CHAVAN | D16: Ahmednagar East RSA | E16: 1754 | F16: 9923563624 | G16: D2 | H16: A | I16: RO | J16: RO A Site-Corpu | K16: R/2023/IN004910/MAH/000499/3203/00151 | L16: 2023-24 | M16: 45349 | N16: =+TODAY()-M16 -> 828 | O16: =+IF(N16<180,"0-6M",IF(N16<365,"6-12M",IF(N16<730,"1-2Y",IF(N16<1095,"2-3Y",IF(N16<1460,"3-4Y",IF(N16<1825,"4-5Y",IF(N16>1825,">5Y"))))))) -> 2-3Y | P16: AHMADNAGAR | Q16: ST | R16: Group 1: Owned land | S16: 30 | T16: 100 | U16: =+S16+T16 -> 130 | W16: Yes | X16: Yes | Z16: Approved | AC16: Yes | AD16: 46143 | AE16: 46174 | AF16: Yes | AG16: NA | AH16: NA | AI16: Yes | AJ16: Yes | AK16: Available | AL16: 46143 | AM16: Yes | AN16: Yes | AO16: Sent | AP16: Yes | AQ16: 4338635 | AS16: 46174 | AT16: Yes | AU16: Yes | AV16: NA | AW16: NA | AX16: Yes | AY16: Received | AZ16: Recieved | BA16: Received | BB16: Received | BC16: Received | BD16: NA | BE16: Received | BF16: Received | BG16: Received | BH16: Yes | BI16: 46143 | BJ16: 46174 | BK16: Yes | BL16: Received | BN16: Yes | BW16: Pending | CB16: SRMP 2023-24 | CC16: Yes | CD16: Yes | CI16: =TEXT(M16,"MMM'YY") -> Feb'24 | CJ16: st | CK16: Yes | CL16: Yes | CM16: Administrative Approval/3203/SL01/2025-2026/141407
A17: 141 | B17: Within 2 Km from DBM English Medium School on either side on Parner to Pune Highway (SH) | C17: SANDIP BHASKAR NIKAM | D17: Ahmednagar West RSA | E17: 1976 | F17: 7875162400 | G17: D2 | H17: A | I17: RO | J17: RO A Site-Corpu | K17: R/2023/IN005327/MAH/000515/3203/00154 | L17: 2023-24 | M17: 45357 | N17: =+TODAY()-M17 -> 820 | O17: =+IF(N17<180,"0-6M",IF(N17<365,"6-12M",IF(N17<730,"1-2Y",IF(N17<1095,"2-3Y",IF(N17<1460,"3-4Y",IF(N17<1825,"4-5Y",IF(N17>1825,">5Y"))))))) -> 2-3Y | P17: AHMADNAGAR | Q17: PHP ( ST ) | R17: Group 1: Owned land | S17: 20 | T17: 80 | U17: =+S17+T17 -> 100 | W17: Yes | X17: Yes | Z17: Approved | AC17: Yes | AD17: =+AL17 -> 46113 | AE17: =+AS17 -> 46174 | AF17: Yes | AG17: NA | AH17: NA | AI17: Yes | AJ17: Yes | AK17: Available | AL17: 46113 | AM17: Yes | AN17: Yes | AO17: Sent | AP17: No | AS17: 46174 | AT17: Yes | AU17: Yes | AV17: NA | AW17: NA | AX17: Yes | AY17: Received | AZ17: Received | BA17: Received | BB17: Received | BC17: NA | BD17: NA | BE17: Received | BF17: Received | BG17: Received | BH17: Yes | BI17: 46113 | BJ17: 46174 | BK17: Yes | BL17: Received | BW17: Pending | CB17: SRMP 2023-24 | CC17: Yes | CD17: Yes | CI17: =TEXT(M17,"MMM'YY") -> Mar'24 | CJ17: st | CK17: Yes | CL17: Yes | CM17: Administrative Approval/3203/SL01/2025-2026/130023
A18: 157 | B18: From Bahul to Sablewadi on LHS on NH (Chakan-Shikrapur Road) | C18: PRAKASH SHANKAR LIMBHORE | D18: Pune Wagholi RSA | E18: 1842 | F18: 8668477069 | G18: D1 | H18: B | I18: RO | J18: RO B Site | K18: R/2024/IN002040/MAH/000089/3203/00004 | L18: 2023-24 | M18: 45456 | N18: =+TODAY()-M18 -> 721 | O18: =+IF(N18<180,"0-6M",IF(N18<365,"6-12M",IF(N18<730,"1-2Y",IF(N18<1095,"2-3Y",IF(N18<1460,"3-4Y",IF(N18<1825,"4-5Y",IF(N18>1825,">5Y"))))))) -> 1-2Y | P18: PUNE | Q18: OPEN | R18: Group 1: Owned land | S18: 40 | T18: 181 | U18: =+S18+T18 -> 221 | W18: Yes | X18: Yes | Y18: =+AP18 -> Yes | Z18: NA | AD18: =+AL18 -> 46023 | AE18: =+AS18 -> 46174 | AF18: Yes | AG18: NA | AH18: NA | AI18: Not Required | AJ18: Not Required | AK18: Yes(P) | AL18: 46023 | AM18: Yes | AN18: Yes | AO18: Approved | AP18: Yes | AQ18: 4337666 | AS18: 46174 | AT18: Yes | AU18: Yes | AV18: NA | AW18: No | AX18: Yes | AY18: yes | AZ18: Yes | BA18: Yes | BB18: Yes | BC18: Yes | BD18: Yes | BE18: NA | BF18: NA | BG18: Received | BH18: Yes | BI18: 46174 | BJ18: 46174 | BK18: Yes | BL18: Received | BM18: NA | BN18: NA | BO18: Not Required | BW18: Pending | CB18: SRMP 2023-24 | CC18: Yes | CD18: Yes | CH18: Yes | CI18: =TEXT(M18,"MMM'YY") -> Jun'24 | CJ18: Open | CK18: Yes | CL18: Yes
A19: 161 | B19: From Km Stone 8 to Km Stone 12 on Ahmednagar-Daund NH | C19: AMRUTA VISHAL LOTAKE | D19: Ahmednagar West RSA | E19: 1716 | F19: 9273739191 | G19: D1 | H19: B | I19: RO | J19: RO B Site | K19: R/2024/IN002247/MAH/000179/3203/00014 | L19: 2023-24 | M19: 45458 | N19: =+TODAY()-M19 -> 719 | O19: =+IF(N19<180,"0-6M",IF(N19<365,"6-12M",IF(N19<730,"1-2Y",IF(N19<1095,"2-3Y",IF(N19<1460,"3-4Y",IF(N19<1825,"4-5Y",IF(N19>1825,">5Y"))))))) -> 1-2Y | P19: AHMADNAGAR | Q19: OPEN | R19: Group 1: Owned land | S19: 35 | T19: 120 | U19: =+S19+T19 -> 155 | W19: Yes | X19: Yes | Y19: =+AP19 -> Yes | Z19: NA | AD19: =+AL19 -> 46143 | AE19: =+AS19 -> 46174 | AF19: Yes | AG19: NA | AH19: NA | AI19: Not Required | AJ19: Not Required | AL19: 46143 | AM19: Yes | AN19: Yes | AO19: Approved | AP19: Yes | AQ19: 4337973 | AS19: 46174 | AT19: Yes | AU19: Yes | AV19: NA | AW19: NA | AX19: Yes | AY19: Received | AZ19: Yes | BA19: Received | BB19: Received | BC19: NA | BD19: NA | BE19: Received | BF19: Received | BG19: Received | BH19: Yes | BI19: 46174 | BJ19: 46199 | BK19: Yes | BL19: Received | BM19: NA | BN19: NA | BO19: Not Required | BW19: Pending | CB19: SRMP 2023-24 | CC19: Yes | CD19: Yes | CI19: =TEXT(M19,"MMM'YY") -> Jun'24 | CJ19: Open | CK19: Yes | CL19: Yes
A20: 200 | B20: From Pingali Budruk To Gondawale Budruk on RHS on Satara Pandharpur Road | C20: AKSHAYKUMAR RAOSAHEB BABAR | D20: Satara East RSA | E20: 1988 | F20: 9765191946 | G20: D1 | H20: B | I20: RO | J20: RO B Site | K20: R/2024/IN002500/MAH/000244/3203/00072 | L20: 2023-24 | M20: 45462 | N20: =+TODAY()-M20 -> 715 | O20: =+IF(N20<180,"0-6M",IF(N20<365,"6-12M",IF(N20<730,"1-2Y",IF(N20<1095,"2-3Y",IF(N20<1460,"3-4Y",IF(N20<1825,"4-5Y",IF(N20>1825,">5Y"))))))) -> 1-2Y | P20: SATARA | Q20: OPEN | R20: Group 1: Owned land | S20: 40 | T20: 110 | U20: =+S20+T20 -> 150 | W20: Yes | X20: Yes | Y20: =+IF(AO20="Approved","Yes",AS20) -> Yes | Z20: NA | AD20: =+AL20 -> 46204 | AE20: =+AS20 -> 46174 | AF20: Yes | AI20: Not Required | AJ20: Not Required | AK20: Available | AL20: 46204 | AM20: 46478 | AN20: Yes | AO20: Approved | AP20: Yes | AQ20: 4338611 | AR20: NHAI Access Pending | AS20: 46174 | AT20: Yes | AU20: Yes | AV20: NA | AW20: NA | AX20: Yes | AY20: Received | AZ20: Received | BA20: Received | BB20: Applied | BC20: Received | BD20: NA | BE20: NA | BF20: NA | BG20: Received | BH20: Yes | BI20: 46143 | BJ20: 46174 | BK20: Yes | BL20: Received | BM20: NA | BN20: NA | BO20: Not Required | BW20: Pending | CB20: SRMP 2023-24 | CC20: Yes | CI20: =TEXT(M20,"MMM'YY") -> Jun'24 | CJ20: Open
A21: 233 | B21: Within 3km From Jawakhede Khalsa Primary Health Sub Centre Towards Miri on Miri-Tisgaon Road (MDR) | C21: CHARUDATTA UDDHAVRAO WAGH | D21: Ahmednagar West RSA | E21: 2106 | F21: 9881916750 | G21: E | H21: B | I21: KSK | J21: KSK-B w/o Reco | K21: R/2024/IN004699/MAH/000470/3203/00129 | L21: 2023-24 | M21: 45699 | N21: =+TODAY()-M21 -> 478 | O21: =+IF(N21<180,"0-6M",IF(N21<365,"6-12M",IF(N21<730,"1-2Y",IF(N21<1095,"2-3Y",IF(N21<1460,"3-4Y",IF(N21<1825,"4-5Y",IF(N21>1825,">5Y"))))))) -> 1-2Y | P21: AHMADNAGAR | Q21: OPEN | R21: Group 1: Owned land | S21: 28 | T21: 80 | U21: =+S21+T21 -> 108 | W21: Yes | X21: Yes | Z21: NA | AD21: =+AL21 -> 46143 | AE21: =+AS21 -> 46174 | AF21: Yes | AG21: NA | AH21: NA | AI21: Not Required | AJ21: Not Required | AL21: 46143 | AM21: Yes | AN21: Yes | AO21: Sent | AP21: No | AR21: LSR received | AS21: 46174 | AT21: Yes | AU21: Yes | AV21: NA | AW21: NA | AX21: Yes | AY21: Received | AZ21: Applied | BA21: Received | BB21: Applied | BC21: NA | BD21: NA | BE21: Received | BF21: Received | BG21: In Process | BH21: Yes | BI21: 46174 | BJ21: 46174 | BK21: Yes | BL21: Received | BM21: NA | BN21: NA | BO21: Not Required | BW21: Pending | CB21: SRMP 2023-24 | CC21: Yes | CD21: Yes | CI21: =TEXT(M21,"MMM'YY") -> Feb'25 | CJ21: Open | CK21: Yes | CL21: Yes | CM21: Administrative Approval/3203/SL01/2026-2027/18664
A22: 253 | B22: From Talegaon Damdhere to Dhanore within 2km on SH (Talegaon Dhamdere - Pimpri Sandas Road) | C22: MANOHAR VISHNU DHAMDHERE | D22: Pune Wagholi RSA | E22: 1783 | F22: 9921224142 | G22: D2 | H22: B | I22: RO | J22: RO B Site | K22: R/2025/IN000578/MAH/000077/3203/00018 | L22: 2023-24 | M22: 45964 | N22: =+TODAY()-M22 -> 213 | O22: =+IF(N22<180,"0-6M",IF(N22<365,"6-12M",IF(N22<730,"1-2Y",IF(N22<1095,"2-3Y",IF(N22<1460,"3-4Y",IF(N22<1825,"4-5Y",IF(N22>1825,">5Y"))))))) -> 6-12M | P22: Pune | Q22: OPEN | R22: Group 1: Owned land | S22: 30 | T22: 77 | U22: =+S22+T22 -> 107 | W22: Yes | X22: Yes | Z22: NA | AC22: Yes | AD22: =+AL22 -> 46143 | AE22: =+AS22 -> 46174 | AF22: Yes | AG22: NA | AH22: NA | AI22: Not Required | AJ22: Not Required | AK22: Available | AL22: 46143 | AM22: Yes | AN22: Yes | AO22: Approved | AP22: Yes | AQ22: 4338612 | AS22: 46174 | AT22: Yes | AU22: yes | AV22: NA | AW22: no | AX22: Yes | AY22: Yes | AZ22: yes | BA22: yes | BB22: Received | BC22: Yes | BD22: Yes | BE22: NA | BF22: NA | BG22: Received | BH22: WIP | BI22: 46167 | BJ22: 46199 | BK22: Yes | BL22: Received | BW22: Pending | CB22: SRMP 2023-24 | CC22: Yes | CD22: Yes | CI22: =TEXT(M22,"MMM'YY") -> Nov'25 | CJ22: Open | CK22: Yes | CL22: Yes
A23: 120 | B23: On RHS From Lohare to Talegaon Dighe on Talegaon Dighe-Loni NH | C23: BHAGWAN RAMESH MUTADAK | D23: Shirdi RSA | E23: 1881 | F23: 9260271806 | G23: D1 | H23: B | I23: RO | J23: RO B Site | K23: R/2023/IN003357/MAH/000374/3203/00115 | L23: 2023-24 | M23: 45315 | N23: =+TODAY()-M23 -> 862 | O23: =+IF(N23<180,"0-6M",IF(N23<365,"6-12M",IF(N23<730,"1-2Y",IF(N23<1095,"2-3Y",IF(N23<1460,"3-4Y",IF(N23<1825,"4-5Y",IF(N23>1825,">5Y"))))))) -> 2-3Y | P23: AHMADNAGAR | Q23: OBC | R23: Group 1: Owned land | S23: 40 | T23: 120 | U23: =+S23+T23 -> 160 | W23: Yes | X23: Yes | Y23: =+AP23 -> Yes | Z23: NA | AD23: =+AL23 -> 46174 | AE23: =+AS23 -> 46204 | AF23: Yes | AG23: NA | AH23: NA | AI23: Not Required | AJ23: Not Required | AL23: 46174 | AN23: Yes | AO23: Approved | AP23: Yes | AQ23: 4337686 | AS23: 46204 | AT23: Yes | AU23: Yes | AV23: NA | AW23: NA | AX23: Yes | AY23: Recieved | AZ23: Applied | BA23: Recieved | BB23: Applied | BC23: Recived | BD23: NA | BE23: Recived | BF23: Recived | BG23: Received | BH23: WIP | BI23: 46234 | BJ23: 46265 | BK23: Yes | BL23: To be applied | BM23: NA | BN23: NA | BO23: Not Required | BW23: Pending | CB23: SRMP 2023-24 | CC23: Yes | CD23: Yes | CI23: =TEXT(M23,"MMM'YY") -> Jan'24 | CJ23: OBC | CK23: Yes | CL23: Yes
A24: 195 | B24: Dehu Phata to Moshi Chowk on RHS on Dehu - Alandi Road | C24: VINOD MARUTI PARANDE | D24: Pimpri Chinchwad RSA | E24: 1949 | F24: 9881999678 | G24: A | H24: B | I24: RO | J24: RO B Site | K24: R/2024/IN002478/MAH/000232/3203/00061 | L24: 2023-24 | M24: 45462 | N24: =+TODAY()-M24 -> 715 | O24: =+IF(N24<180,"0-6M",IF(N24<365,"6-12M",IF(N24<730,"1-2Y",IF(N24<1095,"2-3Y",IF(N24<1460,"3-4Y",IF(N24<1825,"4-5Y",IF(N24>1825,">5Y"))))))) -> 1-2Y | P24: PUNE | Q24: OPEN | R24: Group 2: Firm Offer | S24: 150 | T24: 50 | U24: =+S24+T24 -> 200 | W24: Yes | X24: Yes | Y24: =+AP24 -> Yes | Z24: NA | AA24: Yes | AB24: Yes | AD24: 46204 | AE24: 46204 | AF24: Yes | AI24: Not Required | AJ24: Not Required | AK24: Yes(P) | AL24: 46539 | AN24: Yes | AO24: Approved | AP24: Yes | AQ24: 4337491 | AR24: There is complaint related to Land, Mojani has been cancelled. Matter is subjudiced. Court orders are in our favor. PCMC commissioner has suspended the NOC temporarily.Meeting planned in We expect ervoke of suspension and remojani by Feb'26. | AS24: =+AL24+31 -> 46570 | AT24: Yes | AU24: Yes | AV24: There is court case Going on at Site, hence Commissioning will get delayted. NOC and Mojani has been canc elled by administration based on complaint received for the locaiton | AW24: NA | AX24: Yes | AY24: Received | AZ24: Received | BA24: Received | BB24: Not Required | BC24: Received | BD24: Received | BE24: NA | BF24: NA | BG24: Received | BH24: Yes | BI24: 46266 | BJ24: 46266 | BK24: Yes | BL24: Received | BM24: NA | BN24: NA | BO24: Not Required | BW24: Pending | CB24: SRMP 2023-24 | CC24: Yes | CI24: =TEXT(M24,"MMM'YY") -> Jun'24 | CJ24: Open | CL24: Yes
A25: 208 | B25: Within 4km from Within 4 km from M.M.Nirhali College, Pathardi towards baramat on Baramati-Amrapur SH | C25: VAISHALI RAMESH BARDE | D25: Ahmednagar West RSA | E25: 1837 | F25: 9763122772 | G25: D2 | H25: B | I25: RO | J25: RO B Site | K25: R/2024/IN002781/MAH/000309/3203/00093 | L25: 2023-24 | M25: 45479 | N25: =+TODAY()-M25 -> 698 | O25: =+IF(N25<180,"0-6M",IF(N25<365,"6-12M",IF(N25<730,"1-2Y",IF(N25<1095,"2-3Y",IF(N25<1460,"3-4Y",IF(N25<1825,"4-5Y",IF(N25>1825,">5Y"))))))) -> 1-2Y | P25: AHMADNAGAR | Q25: OBC | R25: Group 1: Owned land | S25: 30 | T25: 70 | U25: =+S25+T25 -> 100 | W25: Yes | X25: Yes | Y25: =+AP25 -> Yes | Z25: NA | AD25: =+AL25 -> 46174 | AE25: =+AS25 -> 46204 | AF25: Yes | AG25: NA | AH25: NA | AI25: Not Required | AJ25: Not Required | AL25: 46174 | AM25: Yes | AN25: Yes | AO25: Approved | AP25: Yes | AQ25: 4337805 | AS25: 46204 | AT25: Yes | AU25: Yes | AV25: NA | AW25: NA | AX25: Yes | AY25: Received | AZ25: Yes | BA25: Received | BB25: Yet to apply | BC25: NA | BD25: NA | BE25: Received | BF25: Received | BG25: Received | BH25: No | BI25: 46291 | BJ25: 46321 | BK25: Yes | BL25: Received | BM25: NA | BN25: NA | BO25: Not Required | BW25: Pending | CB25: SRMP 2023-24 | CC25: Yes | CD25: Yes | CI25: =TEXT(M25,"MMM'YY") -> Jul'24 | CJ25: OBC | CK25: Yes | CL25: Yes
A26: 22 | B26: ON NH-4 BETWEEN KM STONE 760 TO 755 LHS OF PUNE TO SATARA ROAD | C26: Yashodhan Shinde | D26: Satara West RSA | E26: 2018-129 | F26: 9881321999 | G26: D1 | H26: B | I26: RO | J26: RO B Site | K26: M/2018/IN002023/MAH/000207/3203/00064 | L26: 2018-19 | M26: 43536 | N26: =+TODAY()-M26 -> 2641 | O26: =+IF(N26<180,"0-6M",IF(N26<365,"6-12M",IF(N26<730,"1-2Y",IF(N26<1095,"2-3Y",IF(N26<1460,"3-4Y",IF(N26<1825,"4-5Y",IF(N26>1825,">5Y"))))))) -> >5Y | P26: SATARA | Q26: OPEN | R26: Group 2: Firm Offer | S26: 40 | T26: 110 | U26: =+S26+T26 -> 150 | W26: Yes | X26: Yes | Y26: =+AP26 -> Yes | Z26: NA | AD26: =+AL26 -> 46204 | AE26: =+AS26 -> 46235 | AF26: Yes | AG26: NA | AH26: NA | AI26: Not Required | AJ26: Not Required | AL26: 46204 | AM26: Yes | AN26: Yes | AO26: Approved | AP26: Yes | AR26: LSR Awaited | AS26: 46235 | AT26: YES | AU26: YES | AV26: NA | AW26: NA | AX26: YES | AY26: Received | AZ26: Received | BA26: Applied | BB26: Applied | BC26: Received | BD26: NA | BE26: NA | BF26: NA | BG26: In process | BH26: WIP | BI26: 46229 | BJ26: 46260 | BK26: Moujani Awaited | BL26: Yet to Apply | BM26: NA | BN26: NA | BO26: Not Required | BW26: Pending | CB26: SRMP 2018-19 | CC26: Yes | CD26: Yes | CI26: =TEXT(M26,"MMM'YY") -> Mar'19 | CJ26: Open | CK26: Yes | CL26: Yes
A27: 74 | B27: Within 2 km from Chapadgaon Junction towards koregaon on Chapadgaon-Koregaon Road MDR Tal- Karjat | C27: DNYANESHWAR RAMDAS SHINDE | D27: Ahmednagar West RSA | E27: 2095 | F27: 9960927710 | G27: E | H27: B | I27: KSK | J27: KSK-B w/o Reco | K27: R/2023/IN001195/MAH/000083/3203/00024 | L27: 2023-24 | M27: 45261 | N27: =+TODAY()-M27 -> 916 | O27: =+IF(N27<180,"0-6M",IF(N27<365,"6-12M",IF(N27<730,"1-2Y",IF(N27<1095,"2-3Y",IF(N27<1460,"3-4Y",IF(N27<1825,"4-5Y",IF(N27>1825,">5Y"))))))) -> 2-3Y | P27: AHMADNAGAR | Q27: OPEN | R27: Group 1: Owned land | S27: 38 | T27: 70 | U27: =+S27+T27 -> 108 | W27: Yes | X27: Yes | Z27: NA | AD27: =+AL27 -> 46204 | AE27: =+AS27 -> 46235 | AF27: Yes | AG27: NA | AH27: NA | AI27: Not Required | AJ27: Not Required | AL27: 46204 | AM27: Yes | AN27: Yes | AO27: To be Initiated | AP27: No | AR27: LSR Awaited, land change case | AS27: 46235 | AT27: Yes | AU27: Yes | AV27: NA | AW27: NA | AX27: Yes | AY27: Received | AZ27: Applied | BA27: Applied | BB27: Not Required | BC27: NA | BD27: NA | BE27: Applied | BF27: Applied | BG27: In process | BH27: No | BI27: 46291 | BJ27: 46321 | BK27: Yes | BL27: To be applied | BM27: NA | BN27: NA | BO27: Not Required | BW27: Pending | CB27: SRMP 2023-24 | CC27: Yes | CD27: Yes | CI27: =TEXT(M27,"MMM'YY") -> Dec'23 | CJ27: Open | CK27: Yes | CL27: Yes
A28: 162 | B28: Within 3 KM from Varunji Phata Karad Towards Chiplun On Karad Chiplun Road | C28: NITIN DINKAR PATIL | D28: Satara West RSA | E28: 1608 | F28: 8805000393 | G28: D1 | H28: B | I28: RO | J28: RO B Site | K28: R/2024/IN002258/MAH/000183/3203/00018 | L28: 2023-24 | M28: 45458 | N28: =+TODAY()-M28 -> 719 | O28: =+IF(N28<180,"0-6M",IF(N28<365,"6-12M",IF(N28<730,"1-2Y",IF(N28<1095,"2-3Y",IF(N28<1460,"3-4Y",IF(N28<1825,"4-5Y",IF(N28>1825,">5Y"))))))) -> 1-2Y | P28: SATARA | Q28: OPEN | R28: Group 1: Owned land | S28: 80 | T28: 90 | U28: =+S28+T28 -> 170 | W28: Yes | X28: Yes | Y28: =+IF(AO28="Approved","Yes",AS28) -> 46235 | Z28: NA | AD28: =+AL28 -> 46204 | AE28: =+AS28 -> 46235 | AF28: Yes | AG28: NA | AH28: NA | AI28: Not Required | AJ28: Not Required | AL28: 46204 | AM28: Yes | AN28: Yes | AO28: To be Initiated | AP28: No | AR28: LSR Awaited | AS28: 46235 | AT28: YES | AU28: YES | AV28: NA | AW28: NA | AX28: YES | AY28: Received | AZ28: Applied | BA28: Received | BB28: Applied | BC28: Received | BD28: NA | BE28: NA | BF28: NA | BG28: In Process | BH28: WIP | BI28: 46229 | BJ28: 46260 | BK28: Yes | BL28: Received | BM28: NA | BN28: NA | BO28: Not Required | BW28: Pending | BZ28: BS | CB28: SRMP 2023-24 | CC28: Yes | CD28: Yes | CI28: =TEXT(M28,"MMM'YY") -> Jun'24 | CJ28: Open | CK28: Yes | CL28: Yes
A29: 201 | B29: Within 5 Km from Tasawde Toll plaza towards Karad On RHS of Pune to Satara NH | C29: SWATI VIKRAM SHIVDAS | D29: Satara West RSA | E29: 1581 | F29: 9822303957 | G29: D1 | H29: A | I29: RO | J29: RO A Site-Corpu | K29: R/2024/IN002508/MAH/000251/3203/00075 | L29: 2023-24 | M29: 45462 | N29: =+TODAY()-M29 -> 715 | O29: =+IF(N29<180,"0-6M",IF(N29<365,"6-12M",IF(N29<730,"1-2Y",IF(N29<1095,"2-3Y",IF(N29<1460,"3-4Y",IF(N29<1825,"4-5Y",IF(N29>1825,">5Y"))))))) -> 1-2Y | P29: SATARA | Q29: SC | R29: Group 1: Owned land | S29: 40 | T29: 110 | U29: =+S29+T29 -> 150 | W29: Yes | X29: Yes | Z29: Yet to Initiate | AD29: =+AL29 -> 46204 | AE29: =+AS29 -> 46235 | AF29: Yes | AG29: NA | AH29: NA | AI29: Yes | AJ29: Pending | AL29: 46204 | AM29: Yes | AN29: Pending | AO29: To be Initiated | AP29: No | AR29: LSR Awaited | AS29: 46235 | AT29: YES | AU29: YES | AV29: NA | AW29: NA | AX29: YES | AY29: Received | AZ29: Applied | BA29: Received | BB29: Applied | BC29: Received | BD29: NA | BE29: NA | BF29: NA | BG29: In Process | BH29: No | BI29: 46229 | BJ29: 46291 | BK29: Yes | BL29: Received | BN29: Pending | BW29: Pending | BZ29: BS | CA29: Received | CB29: SRMP 2023-24 | CC29: Yes | CD29: Yes | CI29: =TEXT(M29,"MMM'YY") -> Jun'24 | CJ29: SC | CK29: Yes | CL29: Yes
A30: 265 | B30: From Sawarchol to Nimgoan bk. on Sangamer-Kotul SH | C30: HOUSHIRAM MARUTI MECHKAR | D30: Shirdi RSA | E30: 104 | F30: 8805752023 | G30: D2 | H30: A | I30: RO | J30: RO A Site-Corpu | K30: R/2025/IN000872/MAH/000099/3203/00030 | L30: 2023-24 | M30: 46099 | N30: =+TODAY()-M30 -> 78 | O30: =+IF(N30<180,"0-6M",IF(N30<365,"6-12M",IF(N30<730,"1-2Y",IF(N30<1095,"2-3Y",IF(N30<1460,"3-4Y",IF(N30<1825,"4-5Y",IF(N30>1825,">5Y"))))))) -> 0-6M | P30: AHMADNAGAR | Q30: ST | R30: Group 1: Owned land | S30: 25 | T30: 75 | U30: =+S30+T30 -> 100 | W30: Yes | X30: Yes | Z30: Yet to Initiate | AD30: 46204 | AE30: 46235 | AF30: Yes | AI30: In Process | AJ30: Pending | AL30: 46204 | AM30: Pending | AN30: Pending | AO30: To be Initiated | AR30: LSR Awaited | AS30: 46235 | AT30: Yes | AU30: Yes | AV30: LOI given in March 26 and need to see candidate progress for some time to conclude. | AW30: NA | AX30: Yes | AY30: Recieved | AZ30: Yet to Apply | BA30: Yet to Apply | BB30: Yet to Apply | BC30: Yet to Apply | BD30: NA | BE30: Yet to Apply | BF30: Yet to Apply | BG30: In Process | BH30: No | BI30: 46387 | BJ30: 46476 | BK30: Moujani Awaited | BL30: Yet to Apply | BW30: Pending | BZ30: AG on 14.05.2026 | CA30: Ellen and Gosavi on 180526 | CB30: SRMP 2023-24 | CC30: Yes | CI30: =TEXT(M30,"MMM'YY") -> Mar'26 | CJ30: st
A31: 66 | B31: WITH IN 5 KM FROM MORGAON ON LHS OF MORGAON -BARAMATI ROAD , | C31: PURUSHOTTAM KADAM | D31: Pune Tathawade RSA | E31: 54 | F31: 9665080752 | G31: D2 | H31: A | I31: RO | J31: RO A Site-Corpu | K31: M/2023/IN000132/MAH/000015/3203/00009 | L31: 2018-19 | M31: 45047 | N31: =+TODAY()-M31 -> 1130 | O31: =+IF(N31<180,"0-6M",IF(N31<365,"6-12M",IF(N31<730,"1-2Y",IF(N31<1095,"2-3Y",IF(N31<1460,"3-4Y",IF(N31<1825,"4-5Y",IF(N31>1825,">5Y"))))))) -> 3-4Y | P31: PUNE | Q31: SC | R31: Group 1: Owned land | S31: 30 | T31: 90 | U31: =+S31+T31 -> 120 | W31: Yes | X31: Yes | Y31: =+IF(AO31="Approved","Yes",AS31) -> 46266 | Z31: Approved | AD31: =+AL31 -> 46204 | AE31: =+AS31 -> 46266 | AF31: Yes | AG31: NA | AH31: NA | AI31: Yes | AJ31: Yes | AL31: 46204 | AM31: Yes | AO31: Sent | AP31: No | AS31: 46266 | AT31: Yes | AU31: Yes | AV31: PWD NOC pending | AW31: NA | AX31: Yes | AY31: Yes | AZ31: Yes | BA31: Received | BB31: Applied | BC31: Received | BD31: Received | BE31: NA | BF31: NA | BG31: Received | BH31: WIP | BI31: 46204 | BJ31: 46327 | BK31: Yes | BL31: Received | BN31: Pending | BW31: Pending | CB31: SRMP 2018-19 | CC31: Yes | CD31: Yes | CI31: =TEXT(M31,"MMM'YY") -> May'23 | CJ31: SC | CK31: Yes | CL31: Yes | CM31: Administrative Approval/3203/SL01/2025-2026/172925
A32: 90 | B32: Within 3 Km from Ghodegaon Sonai Chowk towards Ahmednagar on Pune-Aurangabad NH | C32: PRITI ATMARAM PAWAR | D32: Ahmednagar East RSA | E32: 96 | F32: 8668904185 | G32: D1 | H32: A | I32: RO | J32: RO A Site-Corpu | K32: R/2023/IN001620/MAH/000160/3203/00058 | L32: 2023-24 | M32: 45274 | N32: =+TODAY()-M32 -> 903 | O32: =+IF(N32<180,"0-6M",IF(N32<365,"6-12M",IF(N32<730,"1-2Y",IF(N32<1095,"2-3Y",IF(N32<1460,"3-4Y",IF(N32<1825,"4-5Y",IF(N32>1825,">5Y"))))))) -> 2-3Y | P32: AHMADNAGAR | Q32: ST | R32: Group 1: Owned land | S32: 40 | T32: 135 | U32: =+S32+T32 -> 175 | W32: Yes | X32: Yes | Y32: =+IF(AO32="Approved","Yes",AS32) -> 46266 | Z32: Yet to Initiate | AD32: =+AL32 -> 46204 | AE32: =+AS32 -> 46266 | AF32: Yes | AG32: NA | AH32: NA | AI32: Yes | AJ32: Yes | AL32: 46204 | AM32: Yes | AN32: Pending | AO32: Sent | AP32: No | AS32: 46266 | AT32: Yes | AU32: Yes | AV32: NA | AW32: NA | AX32: Yes | AY32: Received | AZ32: Applied | BA32: Received | BB32: Applied | BC32: Received | BD32: NA | BE32: Received | BF32: Received | BG32: Received | BH32: WIP | BI32: 46204 | BJ32: 46266 | BK32: Yes | BL32: Received | BN32: Pending | BW32: Pending | CB32: SRMP 2023-24 | CC32: Yes | CD32: Yes | CI32: =TEXT(M32,"MMM'YY") -> Dec'23 | CJ32: st | CK32: Yes | CL32: Yes | CM32: Administrative Approval/3203/SL01/2026-2027/18041
A33: 93 | B33: From Village Walwane to Village Raytale on Supe Sarolakasar Road SH | C33: AKASH SHANTILAL PATHARE | D33: Ahmednagar West RSA | E33: 1592 | F33: 8530744612 | G33: D2 | H33: B | I33: RO | J33: RO B Site | K33: R/2023/IN001673/MAH/000169/3203/00062 | L33: 2023-24 | M33: 45275 | N33: =+TODAY()-M33 -> 902 | O33: =+IF(N33<180,"0-6M",IF(N33<365,"6-12M",IF(N33<730,"1-2Y",IF(N33<1095,"2-3Y",IF(N33<1460,"3-4Y",IF(N33<1825,"4-5Y",IF(N33>1825,">5Y"))))))) -> 2-3Y | P33: AHMADNAGAR | Q33: OBC | R33: Group 1: Owned land | S33: 25 | T33: 80 | U33: =+S33+T33 -> 105 | W33: Yes | X33: Yes | Z33: NA | AD33: 46235 | AE33: 46266 | AF33: Yes | AG33: NA | AH33: NA | AI33: Not Required | AJ33: Not Required | AL33: 46266 | AM33: Yes | AN33: Yes | AO33: To be Initiated | AP33: No | AR33: LSR Awaited | AS33: 46296 | AT33: Yes | AU33: Yes | AV33: NA | AW33: NA | AX33: Yes | AY33: Received | AZ33: Applied | BA33: Applied | BB33: Yet to Apply | BC33: NA | BD33: NA | BE33: Applied | BF33: Applied | BG33: In process | BH33: No | BI33: 46291 | BJ33: 46321 | BK33: Yes | BL33: To be applied | BM33: NA | BN33: NA | BO33: Not Required | BW33: Pending | CB33: SRMP 2023-24 | CC33: Yes | CD33: Yes | CI33: =TEXT(M33,"MMM'YY") -> Dec'23 | CJ33: OBC | CK33: Yes | CL33: Yes
A34: 109 | B34: From Village Pargaon Shingave to Village Manjarwadi on RHS on SH | C34: RAMKRUSHNA RAMCHANDRA JANBHOR | D34: Pune Wagholi RSA | E34: 2076 | F34: 9860520267 | G34: D2 | H34: B | I34: RO | J34: RO B Site | K34: R/2023/IN003093/MAH/000338/3203/00098 | L34: 2023-24 | M34: 45309 | N34: =+TODAY()-M34 -> 868 | O34: =+IF(N34<180,"0-6M",IF(N34<365,"6-12M",IF(N34<730,"1-2Y",IF(N34<1095,"2-3Y",IF(N34<1460,"3-4Y",IF(N34<1825,"4-5Y",IF(N34>1825,">5Y"))))))) -> 2-3Y | P34: PUNE | Q34: OPEN | R34: Group 1: Owned land | S34: 40 | T34: 80 | U34: =+S34+T34 -> 120 | W34: Yes | X34: Yes | Y34: =+IF(AO34="Approved","Yes",AS34) -> Yes | Z34: NA | AD34: 46235 | AE34: 46266 | AF34: Yes | AG34: NA | AH34: NA | AI34: Not Required | AJ34: Not Required | AL34: 46266 | AM34: Yes | AN34: Yes | AO34: Approved | AP34: Yes | AQ34: 4338613 | AR34: PWD junction issue. Land comes within 300 Mt of junction. PWQD file sent for relaxation approval | AS34: 46296 | AT34: Yes | AU34: Yes but in next FY | AV34: PWD junction issue. Land comes within 300 Mt of junction. PWQD file sent for relaxation approval | AW34: No | AX34: Yes | AY34: Yes | AZ34: Yes | BA34: Yes | BB34: Applies | BC34: Yes | BD34: yes | BE34: NA | BF34: NA | BG34: Received | BH34: No | BI34: 46143 | BJ34: 46174 | BK34: Yes | BL34: Received | BM34: NA | BN34: NA | BO34: Not Required | BW34: Pending | CB34: SRMP 2023-24 | CC34: Yes | CD34: Yes | CI34: =TEXT(M34,"MMM'YY") -> Jan'24 | CJ34: Open | CK34: Yes | CL34: Yes
A35: 124 | B35: Moshi Chowk on Pune Nashik Road to Talwade Chowk on LHS on Dehu Alandi Road (within PCMC Limits) | C35: SACHIN PANDURANG BORATE | D35: Pimpri Chinchwad RSA | E35: 1672 | F35: 9356705562 | G35: A | H35: A | I35: RO | J35: RO A Site | K35: R/2023/IN003662/MAH/000405/3203/00125 | L35: 2023-24 | M35: 45323 | N35: =+TODAY()-M35 -> 854 | O35: =+IF(N35<180,"0-6M",IF(N35<365,"6-12M",IF(N35<730,"1-2Y",IF(N35<1095,"2-3Y",IF(N35<1460,"3-4Y",IF(N35<1825,"4-5Y",IF(N35>1825,">5Y"))))))) -> 2-3Y | P35: PUNE | Q35: OPEN | R35: Group 1: Owned land | S35: 150 | T35: 50 | U35: =+S35+T35 -> 200 | W35: Yes | X35: Yes | Y35: =+AP35 -> No | Z35: Approved | AD35: 46235 | AE35: 46266 | AF35: Yes | AG35: NA | AH35: NA | AI35: Yes | AJ35: Yes | AK35: Yes(P) | AL35: 46357 | AM35: Yes | AN35: Yes | AO35: Sent | AP35: No | AS35: 46296 | AT35: Yes | AU35: Yes | AV35: NA | AW35: NA | AX35: Yes | AY35: Received | AZ35: Received | BA35: Received | BB35: Not Required | BC35: Received | BD35: Received | BE35: NA | BF35: NA | BG35: Received | BH35: WIP | BI35: 46296 | BJ35: 46327 | BK35: Yes | BL35: Received | BN35: Yes | BW35: Pending | CB35: SRMP 2023-24 | CC35: Yes | CD35: Yes | CI35: =TEXT(M35,"MMM'YY") -> Feb'24 | CJ35: Open | CK35: Yes | CL35: Yes | CM35: Administrative Approval/3203/SL01/2026-2027/19224
A36: 173 | B36: From Kapurhol to Kikvi on RHS on NH (Pune-Bangalore Highway) | C36: SWAPNIL RAMDAS CHARWAD | D36: Pune Tathawade RSA | E36: 1712 | F36: 9766110001 | G36: D1 | H36: B | I36: RO | J36: RO B Site | K36: R/2024/IN002366/MAH/000196/3203/00030 | L36: 2023-24 | M36: 45460 | N36: =+TODAY()-M36 -> 717 | O36: =+IF(N36<180,"0-6M",IF(N36<365,"6-12M",IF(N36<730,"1-2Y",IF(N36<1095,"2-3Y",IF(N36<1460,"3-4Y",IF(N36<1825,"4-5Y",IF(N36>1825,">5Y"))))))) -> 1-2Y | P36: PUNE | Q36: OPEN | R36: Group 1: Owned land | S36: 40 | T36: 120 | U36: =+S36+T36 -> 160 | W36: Yes | X36: Yes | Y36: =+AP36 -> Yes | Z36: NA | AD36: =+AL36 -> 46204 | AE36: =+AS36 -> 46266 | AF36: Yes | AG36: NA | AH36: NA | AI36: Not Required | AJ36: Not Required | AL36: 46204 | AM36: Yes | AN36: Yes | AO36: Approved | AP36: Yes | AQ36: 4338053 | AS36: 46266 | AT36: Yes | AU36: Yes | AV36: Provisional NH NOC pending and SP NOC pending | AW36: NA | AX36: Yes | AY36: Yes | AZ36: Yes | BA36: Applied | BB36: Applied | BC36: Received | BD36: Received | BE36: NA | BF36: NA | BG36: Received | BH36: WIP | BI36: 46204 | BJ36: 46327 | BK36: Yes | BL36: Received | BM36: NA | BN36: NA | BO36: Not Required | BW36: Pending | CB36: SRMP 2023-24 | CC36: Yes | CD36: Yes | CI36: =TEXT(M36,"MMM'YY") -> Jun'24 | CJ36: Open | CK36: Yes | CL36: Yes
A37: 229 | B37: Bhose to Shelpimpalgaon on LHS on Chakan Shikrapur Road | C37: RAJABHAU MOTIRAM BANSODE | D37: Pimpri Chinchwad RSA | E37: 2030 | F37: 7030954444 | G37: D1 | H37: A | I37: RO | J37: RO A Site-Corpu | K37: R/2024/IN004518/MAH/000463/3203/00124 | L37: 2023-24 | M37: 45659 | N37: =+TODAY()-M37 -> 518 | O37: =+IF(N37<180,"0-6M",IF(N37<365,"6-12M",IF(N37<730,"1-2Y",IF(N37<1095,"2-3Y",IF(N37<1460,"3-4Y",IF(N37<1825,"4-5Y",IF(N37>1825,">5Y"))))))) -> 1-2Y | P37: PUNE | Q37: SC | R37: Group 1: Owned land | S37: 30 | T37: 120 | U37: =+S37+T37 -> 150 | W37: Yes | X37: Yes | Y37: =+IF(AO37="Approved","Yes",AS37) -> Yes | Z37: Approved | AA37: NA | AD37: =+AL37 -> 46023 | AE37: =+AS37 -> 46266 | AF37: Yes | AG37: NA | AH37: NA | AI37: Yes | AJ37: Yes | AK37: Yes(P) | AL37: 46023 | AM37: Yes | AN37: Yes | AO37: Approved | AP37: Yes | AS37: 46266 | AT37: Yes | AU37: Yes | AV37: NA | AW37: NA | AX37: Yes | AY37: Received | AZ37: Received | BA37: Received | BB37: Received | BC37: Received | BD37: Received | BE37: NA | BF37: NA | BG37: Received | BH37: Yes | BI37: 46266 | BJ37: 46296 | BK37: Yes | BL37: Received | BN37: Yes | BW37: Pending | CB37: SRMP 2023-24 | CC37: Yes | CD37: Yes | CI37: =TEXT(M37,"MMM'YY") -> Jan'25 | CJ37: SC | CK37: Yes | CL37: Yes | CM37: Administrative Approval/3203/SL01/2025-2026/130494
A38: 104 | B38: Within 3 Km From Dr Ambedkar Chowk (Kakadi) towards Korhale on RHS of Airport-Shirdi Road (MDR) | C38: YASRAJ HARISHCHANDRA BHUSHARI | D38: Shirdi RSA | E38: 2111 | F38: 9112735899 | G38: E | H38: A | I38: KSK | J38: KSK-A w/o Reco | K38: R/2023/IN002952/MAH/000313/3203/00092 | L38: 2023-24 | M38: 45307 | N38: =+TODAY()-M38 -> 870 | O38: =+IF(N38<180,"0-6M",IF(N38<365,"6-12M",IF(N38<730,"1-2Y",IF(N38<1095,"2-3Y",IF(N38<1460,"3-4Y",IF(N38<1825,"4-5Y",IF(N38>1825,">5Y"))))))) -> 2-3Y | P38: AHMADNAGAR | Q38: OBC | R38: Group 1: Owned land | S38: 30 | T38: 120 | U38: =+S38+T38 -> 150 | W38: Yes | X38: Yes | Y38: =+IF(AO38="Approved","Yes",AS38) -> Yes | Z38: Approved | AD38: 46266 | AE38: 46296 | AF38: Yes | AI38: Yes | AJ38: Yes | AL38: 46266 | AM38: Pending | AN38: Yes | AO38: Approved | AP38: Yes | AQ38: 4338490 | AR38: frontage is 30 M against PWD requirement of 35 Mt. | AS38: 46296 | AT38: Yes | AU38: Yes | AV38: NA | AW38: NA | AX38: Yes | AY38: Recieved | AZ38: Applied | BA38: Recieved | BB38: Applied | BC38: Recived | BD38: NA | BE38: Recived | BF38: Recived | BG38: Received | BH38: No | BI38: 46265 | BJ38: 46387 | BK38: Yes | BL38: Received | BN38: Pending | BW38: Pending | CB38: SRMP 2023-24 | CC38: Yes | CI38: =TEXT(M38,"MMM'YY") -> Jan'24 | CJ38: OBC
A39: 122 | B39: AT JEUR ON AHMEDNAGAR-AURANGABAD ROAD | C39: RANJANA RAJIV SALVE | D39: Ahmednagar East RSA | E39: 2018-766 | F39: 9309939919 | G39: D1 | H39: A | I39: RO | J39: RO A Site-Corpu | K39: M/2023/IN003549/MAH/000389/3203/00121 | L39: 2018-19 | M39: 45321 | N39: =+TODAY()-M39 -> 856 | O39: =+IF(N39<180,"0-6M",IF(N39<365,"6-12M",IF(N39<730,"1-2Y",IF(N39<1095,"2-3Y",IF(N39<1460,"3-4Y",IF(N39<1825,"4-5Y",IF(N39>1825,">5Y"))))))) -> 2-3Y | P39: AHMADNAGAR | Q39: SC | R39: Group 1: Owned land | S39: 30 | T39: 120 | U39: =+S39+T39 -> 150 | W39: Yes | X39: Yes | Z39: Yet to Initiate | AD39: 46266 | AE39: 46296 | AF39: Yes | AG39: NA | AH39: NA | AI39: Yes | AJ39: Pending | AL39: 46266 | AM39: Yes | AN39: Pending | AO39: To be Initiated | AP39: No | AR39: Negotiation Pending | AS39: 46296 | AT39: Yes | AU39: Yes | AV39: NA | AW39: NA | AX39: Yes | AY39: Received | AZ39: Yet to Apply | BA39: Received | BB39: Applied | BC39: Received | BD39: NA | BE39: Received | BF39: Received | BG39: Received | BH39: No | BI39: 46388 | BJ39: 46419 | BK39: Yes | BW39: Pending | BZ39: Received | CA39: Received | CB39: SRMP 2018-19 | CC39: Yes | CI39: =TEXT(M39,"MMM'YY") -> Jan'24 | CJ39: SC
A40: 132 | B40: Within 2 KM from Medha Bus Stand towards Satara on Mahabaleshwar Satara Road | C40: RUPALI KISAN SABLE | D40: Satara West RSA | E40: 97 | F40: 8788144518 | G40: D2 | H40: A | I40: RO | J40: RO A Site-Corpu | K40: R/2023/IN004334/MAH/000466/3203/00142 | L40: 2023-24 | M40: 45338 | N40: =+TODAY()-M40 -> 839 | O40: =+IF(N40<180,"0-6M",IF(N40<365,"6-12M",IF(N40<730,"1-2Y",IF(N40<1095,"2-3Y",IF(N40<1460,"3-4Y",IF(N40<1825,"4-5Y",IF(N40>1825,">5Y"))))))) -> 2-3Y | P40: SATARA | Q40: ST | R40: Group 1: Owned land | S40: 22 | T40: 90 | U40: =+S40+T40 -> 112 | W40: Yes | X40: Yes | Y40: =+IF(AO40="Approved","Yes",AS40) -> 46296 | Z40: Yet to Initiate | AD40: =+AL40 -> 46266 | AE40: =+AS40 -> 46296 | AF40: Yes | AG40: NA | AH40: NA | AI40: Yes | AJ40: Pending | AL40: 46266 | AM40: Pending | AN40: Pending | AO40: To be Initiated | AP40: No | AR40: LSR Awaited, Financially week | AS40: 46296 | AT40: YES | AU40: YES | AV40: NA | AW40: NA | AX40: YES | AY40: Received | AZ40: Applied | BA40: Applied | BB40: NA | BC40: Received | BD40: NA | BE40: NA | BF40: NA | BG40: In Process | BI40: 46291 | BJ40: 46352 | BK40: Yes | BL40: Received | BN40: Pending | BW40: Pending | BZ40: BS | CA40: Received | CB40: SRMP 2023-24 | CC40: Yes | CD40: Yes | CI40: =TEXT(M40,"MMM'YY") -> Feb'24 | CJ40: st | CK40: Yes | CL40: Yes
...

Sheet Summary
C1: Total | M1: A | N1: A | O1: A | P1: A | Q1: A | R1: A | S1: A | T1: A | U1: A | V1: D1 | W1: D1 | X1: D1 | Y1: D1 | Z1: D1 | AA1: D1 | AB1: D1 | AC1: D1 | AD1: D1 | AE1: D2 | AF1: D2 | AG1: D2 | AH1: D2 | AI1: D2 | AJ1: D2 | AK1: D2 | AL1: D2 | AM1: D2 | AN1: C | AO1: C | AP1: C | AQ1: C | AR1: C | AS1: C | AT1: C | AU1: C | AV1: C | AW1: E | AX1: E | AY1: E | AZ1: E | BA1: E | BB1: E | BC1: E | BD1: E | BE1: E | BF1: Already Commissioned | BR1: Total
C2: Commissionable in this FY | F2: Drawing | G2: NOC Available | J2: IO Available | M2: Commissionable in this FY | P2: NOC Available | S2: IO Available | V2: Commissionable in this FY | Y2: NOC Available | AB2: IO Available | AE2: Commissionable in this FY | AH2: NOC Available | AK2: IO Available | AN2: Commissionable in this FY | AQ2: NOC Available | AT2: IO Available | AW2: Commissionable in this FY | AZ2: NOC Available | BC2: IO Available | BF2: A | BG2: A | BH2: B | BI2: B | BJ2: C | BK2: C | BL2: D1 | BM2: D1 | BN2: D2 | BO2: D2 | BP2: E | BQ2: E | BR2: All COM
A3: RSA | B3: Total | C3: A | D3: B | E3: Total | F3: A+B | G3: A | H3: B | I3: Total | J3: A | K3: B | L3: Total | M3: A | N3: B | O3: otal | P3: A | Q3: B | R3: Total | S3: A | T3: B | U3: Total | V3: A | W3: B | X3: Total | Y3: A | Z3: B | AA3: Total | AB3: A | AC3: B | AD3: Total | AE3: A | AF3: B | AG3: Total | AH3: A | AI3: B | AJ3: Total | AK3: A | AL3: B | AM3: Total | AN3: A | AO3: B | AP3: Total | AQ3: A | AR3: B | AS3: Total | AT3: A | AU3: B | AV3: Total | AW3: A | AX3: B | AY3: Total | AZ3: A | BA3: B | BB3: Total | BC3: A | BD3: B | BE3: Total | BF3: A | BG3: B | BH3: A | BI3: B | BJ3: A | BK3: B | BL3: A | BM3: B | BN3: A | BO3: B | BP3: A | BQ3: B
